Workbook

Sheet WACC
B2: weighted average cost of capital
B4: all figures are in inr unless stated otherwise
F5: (this is not valuation of wacc, its just a modelling of wacc)
B7: Peer comps
J8: debt/ | K8: debt/ | L8: levered | M8: unlevered
B9: name of the comp | F9: country | G9: total debt | H9: total equity | I9: taxrate 1 | J9: equity | K9: capital | L9: beta 2 | M9: beta 3
B11: avenue supermart | F11: India | G11: ='beta-comps'!E5 -> 16091899904 | H11: ='beta-comps'!D5 -> 2605665222656 | I11: 0.3 | J11: =G11/H11 -> 0.0061757358 | K11: =G11/(G11+H11) -> 0.0061378301 | L11: ='Beta dmart'!P6 -> 0.15985968 | M11: =L11/(1+(1-I11)*J11) -> 0.15917158
B12: trent | F12: India | G12: ='beta-comps'!E6 -> 23485700096 | H12: ='beta-comps'!D6 -> 1489847975936 | I12: 0.3 | J12: =G12/H12 -> 0.015763823 | K12: =G12/(G12+H12) -> 0.015519182 | L12: ='beta trent'!P6 -> 0.47333487 | M12: =L12/(1+(1-I12)*J12) -> 0.46816878
B13: vedant fashions | F13: India | G13: ='beta-comps'!E7 -> 4637550080 | H13: ='beta-comps'!D7 -> 118461530112 | I13: 0.3 | J13: =G13/H13 -> 0.039148153 | K13: =G13/(G13+H13) -> 0.037673312 | L13: ='beta manavyar'!P6 -> 0.0033389176 | M13: =L13/(1+(1-I13)*J13) -> 0.0032498594
B14: aditya birla fashion | F14: India | G14: ='beta-comps'!E8 -> 56652398592 | H14: ='beta-comps'!D8 -> 85499035648 | I14: 0.3 | J14: =G14/H14 -> 0.66260863 | K14: =G14/(G14+H14) -> 0.39853554 | L14: ='beta abfrl'!P6 -> 0.34585093 | M14: =L14/(1+(1-I14)*J14) -> 0.23626505
B15: mtero brands | F15: India | G15: ='beta-comps'!E9 -> 14386299904 | H15: ='beta-comps'!D9 -> 285401055232 | I15: 0.3 | J15: =G15/H15 -> 0.050407312 | K15: =G15/(G15+H15) -> 0.047988348 | L15: ='beta mterobrand'!P6 -> 0.037661612 | M15: =L15/(1+(1-I15)*J15) -> 0.03637801
H17: average | I17: =AVERAGE(I11:I15) -> 0.3 | J17: =AVERAGE(J11:J15) -> 0.15482073 | K17: =AVERAGE(K11:K15) -> 0.10117084 | L17: =AVERAGE(L11:L15) -> 0.2040092 | M17: =AVERAGE(M11:M15) -> 0.18064665
H18: median | I18: =MEDIAN(I11:I15) -> 0.3 | J18: =MEDIAN(J11:J15) -> 0.039148153 | K18: =MEDIAN(K11:K15) -> 0.037673312 | L18: =MEDIAN(L11:L15) -> 0.15985968 | M18: =MEDIAN(M11:M15) -> 0.15917158
B21: Cost of Debt | L21: Cost of Debt | M21: Equity
B23: pre-tax cost of debt | H23: 0.084 | L23: rist free rate | Q23: 0.065 | R23: (find from investing.com india 10 yr data)
B24: tax rate | H24: 0.3 | L24: equity risk premium | Q24: ='valuation of rm'!H11-WACC!Q23 -> 0.086492308
B25: post tax cost of debt | H25: =H23*(1-H24) -> 0.0588 | L25: levered beta 4 | Q25: =R34 -> 0.17171285 | R25: (our prefrence should be peer company beta)
L26: cost of equity | Q26: =Q23+Q24*Q25 -> 0.079851841
B29: Capital Structure | L29: levered beta
G31: current | H31: target | L31: comps median unlevered beta | R31: =M18 -> 0.15917158
B32: total debt | F32: =G11 -> 16091899904 | G32: =F32/$F$34 -> 0.0061378301 | H32: =K17 -> 0.10117084 | L32: target debt/equity | R32: =H36 -> 0.11255848
B33: makret capitalization | F33: =H11 -> 2605665222656 | G33: =F33/$F$34 -> 0.99386217 | H33: =H34-H32 -> 0.89882916 | L33: tax rate | R33: =H24 -> 0.3
B34: total capital | F34: =SUM(F32:F33) -> 2621757122560 | G34: =F34/$F$34 -> 1 | H34: =G34 -> 1 | L34: levered beta | R34: =R31*(1+(1-R33)*R32) -> 0.17171285
B36: debt/equity | G36: =G32/G33 -> 0.0061757358 | H36: =H32/H33 -> 0.11255848 | L36: weighted average cost of capital
L38: cost of equity | R38: =Q26 -> 0.079851841
B39: notes: | L39: equity weight | R39: =H33 -> 0.89882916
B40: 1. tax rate considered as marginal tax rate for the country
B41: 2. levered beta is based on 5 year monthly data | L41: cost of debt | R41: =H25 -> 0.0588
B42: 3. unlevered beta = levered beta(1+(1-tax rate)*(debt/equity) | L42: debt weight | R42: =H32 -> 0.10117084
L44: WACC | R44: =(R38*R39)+(R41+R42) -> 0.23174401

Sheet Beta dmart
O2: these are the three ways
B3: dmart | G3: nifty | K3: beta drifting | O3: of finding beta :
O4: beta 1 | P4: =SLOPE(D7:D110,I7:I110) -> 0.15985968
A5: date | B5: prices | C5: weekly return | F5: date | G5: prices | H5: weekly return | K5: levered raw beta | L5: =P6 -> 0.15985968 | O5: beta 2 | P5: =_xlfn.COVARIANCE.S(D6:D110,I6:I110)/_xlfn.VAR.S(I6:I110) -> 0.15985968
A6: 45327 | B6: 21782.5 | F6: 45327 | G6: 3719.2 | K6: beta weigth | L6: 0.75 | O6: beta 3 | P6: =O28 -> 0.15985968
A7: 45334 | B7: 22040.699 | D7: =B7/B6-1 -> 0.011853516 | F7: 45334 | G7: 3693.3 | I7: =G7/G6-1 -> -0.006963837
A8: 45341 | B8: 22212.699 | D8: =B8/B7-1 -> 0.0078037452 | F8: 45341 | G8: 3840.55 | I8: =G8/G7-1 -> 0.039869493 | K8: market beta | L8: 1
A9: 45348 | B9: 22338.75 | D9: =B9/B8-1 -> 0.005674717 | F9: 45348 | G9: 3884.1499 | I9: =G9/G8-1 -> 0.011352502 | K9: market beta weight= | L9: 0.25
A10: 45355 | B10: 22493.551 | D10: =B10/B9-1 -> 0.0069296976 | F10: 45355 | G10: 3925.95 | I10: =G10/G9-1 -> 0.010761698
A11: 45362 | B11: 22023.35 | D11: =B11/B10-1 -> -0.020903822 | F11: 45362 | G11: 3932.1001 | I11: =G11/G10-1 -> 0.0015665372 | K11: adjusted beta | L11: =L6*L5+L9*L8 -> 0.36989476 | N11: SUMMARY OUTPUT
A12: 45369 | B12: 22096.75 | D12: =B12/B11-1 -> 0.0033328441 | F12: 45369 | G12: 4297.6001 | I12: =G12/G11-1 -> 0.092952873
A13: 45376 | B13: 22326.9 | D13: =B13/B12-1 -> 0.010415577 | F13: 45376 | G13: 4525.6001 | I13: =G13/G12-1 -> 0.053052866 | N13: Regression Statistics
A14: 45383 | B14: 22513.699 | D14: =B14/B13-1 -> 0.0083665365 | F14: 45383 | G14: 4619.25 | I14: =G14/G13-1 -> 0.020693367 | N14: Multiple R | O14: 0.40979868
A15: 45390 | B15: 22519.4 | D15: =B15/B14-1 -> 0.00025323124 | F15: 45390 | G15: 4765.0498 | I15: =G15/G14-1 -> 0.031563523 | N15: R Square | O15: 0.16793496
A16: 45397 | B16: 22147 | D16: =B16/B15-1 -> -0.01653687 | F16: 45397 | G16: 4696 | I16: =G16/G15-1 -> -0.014490888 | N16: Adjusted R Square | O16: 0.15977746
A17: 45404 | B17: 22419.949 | D17: =B17/B16-1 -> 0.012324433 | F17: 45404 | G17: 4553.1499 | I17: =G17/G16-1 -> -0.030419527 | N17: Standard Error | O17: 0.015524269
A18: 45411 | B18: 22475.85 | D18: =B18/B17-1 -> 0.0024933326 | F18: 45411 | G18: 4612.3501 | I18: =G18/G17-1 -> 0.013002031 | N18: Observations | O18: 104
A19: 45418 | B19: 22055.199 | D19: =B19/B18-1 -> -0.018715661 | F19: 45418 | G19: 4796.7998 | I19: =G19/G18-1 -> 0.039990396
A20: 45425 | B20: 22466.1 | D20: =B20/B19-1 -> 0.018630545 | F20: 45425 | G20: 4670.6499 | I20: =G20/G19-1 -> -0.026298763 | N20: ANOVA
A21: 45432 | B21: 22957.1 | D21: =B21/B20-1 -> 0.021855151 | F21: 45432 | G21: 4684.5 | I21: =G21/G20-1 -> 0.002965347 | O21: df | P21: SS | Q21: MS | R21: F | S21: Significance F
A22: 45439 | B22: 22530.699 | D22: =B22/B21-1 -> -0.018573792 | F22: 45439 | G22: 4302.1499 | I22: =G22/G21-1 -> -0.081620258 | N22: Regression | O22: 1 | P22: 0.0049614236 | Q22: 0.0049614236 | R22: 20.586571 | S22: 1.5607277e-05
A23: 45446 | B23: 23290.15 | D23: =B23/B22-1 -> 0.033707395 | F23: 45446 | G23: 4747.25 | I23: =G23/G22-1 -> 0.10345992 | N23: Residual | O23: 102 | P23: 0.024582298 | Q23: 0.00024100292
A24: 45453 | B24: 23465.6 | D24: =B24/B23-1 -> 0.0075331939 | F24: 45453 | G24: 4739.9502 | I24: =G24/G23-1 -> -0.0015376912 | N24: Total | O24: 103 | P24: 0.029543722
A25: 45460 | B25: 23501.1 | D25: =B25/B24-1 -> 0.0015128529 | F25: 45460 | G25: 4804.8501 | I25: =G25/G24-1 -> 0.013692106
A26: 45467 | B26: 24010.6 | D26: =B26/B25-1 -> 0.021679837 | F26: 45467 | G26: 4716.75 | I26: =G26/G25-1 -> -0.01833566 | O26: Coefficients | P26: Standard Error | Q26: t Stat | R26: P-value | S26: Lower 95% | T26: Upper 95% | U26: Lower 95.0% | V26: Upper 95.0%
A27: 45474 | B27: 24323.85 | D27: =B27/B26-1 -> 0.013046321 | F27: 45474 | G27: 4853.1001 | I27: =G27/G26-1 -> 0.028907637 | N27: Intercept | O27: 0.0014651649 | P27: 0.0015230156 | Q27: 0.96201565 | R27: 0.33831682 | S27: -0.0015557294 | T27: 0.0044860592 | U27: -0.0015557294 | V27: 0.0044860592
A28: 45481 | B28: 24502.15 | D28: =B28/B27-1 -> 0.0073302863 | F28: 45481 | G28: 4943.6499 | I28: =G28/G27-1 -> 0.018658137 | N28: X Variable 1 | O28: 0.15985968 | P28: 0.035232782 | Q28: 4.5372426 | R28: 1.5607277e-05 | S28: 0.089975623 | T28: 0.22974373 | U28: 0.089975623 | V28: 0.22974373
A29: 45488 | B29: 24530.9 | D29: =B29/B28-1 -> 0.0011733664 | F29: 45488 | G29: 5010.7002 | I29: =G29/G28-1 -> 0.013562913
A30: 45495 | B30: 24834.85 | D30: =B30/B29-1 -> 0.012390463 | F30: 45495 | G30: 5071.6001 | I30: =G30/G29-1 -> 0.01215397
A31: 45502 | B31: 24717.699 | D31: =B31/B30-1 -> -0.0047171774 | F31: 45502 | G31: 4909.7002 | I31: =G31/G30-1 -> -0.031922845
A32: 45509 | B32: 24367.5 | D32: =B32/B31-1 -> -0.014167954 | F32: 45509 | G32: 4989.9502 | I32: =G32/G31-1 -> 0.016345194
A33: 45516 | B33: 24541.15 | D33: =B33/B32-1 -> 0.0071263113 | F33: 45516 | G33: 5021.2998 | I33: =G33/G32-1 -> 0.0062825496
A34: 45523 | B34: 24823.15 | D34: =B34/B33-1 -> 0.011490904 | F34: 45523 | G34: 4901.5 | I34: =G34/G33-1 -> -0.023858325
A35: 45530 | B35: 25235.9 | D35: =B35/B34-1 -> 0.016627624 | F35: 45530 | G35: 4927.4502 | I35: =G35/G34-1 -> 0.0052943375
A36: 45537 | B36: 24852.15 | D36: =B36/B35-1 -> -0.015206511 | F36: 45537 | G36: 5303.4502 | I36: =G36/G35-1 -> 0.076307215
A37: 45544 | B37: 25356.5 | D37: =B37/B36-1 -> 0.020294003 | F37: 45544 | G37: 5187.0498 | I37: =G37/G36-1 -> -0.02194805
A38: 45551 | B38: 25790.949 | D38: =B38/B37-1 -> 0.017133643 | F38: 45551 | G38: 5320.5498 | I38: =G38/G37-1 -> 0.025737173
A39: 45558 | B39: 26178.949 | D39: =B39/B38-1 -> 0.015044037 | F39: 45558 | G39: 5102.2998 | I39: =G39/G38-1 -> -0.041020197
A40: 45565 | B40: 25014.6 | D40: =B40/B39-1 -> -0.04447656 | F40: 45565 | G40: 4737.5498 | I40: =G40/G39-1 -> -0.071487371
... A110: 46055 | B110: 25556.85 | D110: =B110/B109-1 -> 0.029461718 | F110: 46055 | G110: 3883.8999 | I110: =G110/G109-1 -> 0.074770998

Sheet beta trent
O2: these are the three ways
B3: trent | G3: nifty | K3: beta drifting | O3: of finding beta :
O4: beta 1 | P4: =SLOPE(D7:D110,I7:I110) -> 0.47333487
A5: date | B5: prices | C5: weekly return | F5: date | G5: prices | H5: weekly return | K5: levered raw beta | L5: =P5 -> 0.47333487 | O5: beta 2 | P5: =_xlfn.COVARIANCE.S(D6:D110,I6:I110)/_xlfn.VAR.S(I6:I110) -> 0.47333487
A6: 45327 | B6: 3753.7205 | F6: 45327 | G6: 3719.2 | K6: beta weigth | L6: 0.75 | O6: beta 3 | P6: =M31 -> 0.47333487
A7: 45334 | B7: 4018.3594 | D7: =B7/B6-1 -> 0.070500433 | F7: 45334 | G7: 3693.3 | I7: =G7/G6-1 -> -0.006963837
A8: 45341 | B8: 3879.7747 | D8: =B8/B7-1 -> -0.034487885 | F8: 45341 | G8: 3840.55 | I8: =G8/G7-1 -> 0.039869493 | K8: market beta | L8: 1
A9: 45348 | B9: 3895.2004 | D9: =B9/B8-1 -> 0.0039759477 | F9: 45348 | G9: 3884.1499 | I9: =G9/G8-1 -> 0.011352502 | K9: market beta weight= | L9: 0.25
A10: 45355 | B10: 3946.0715 | D10: =B10/B9-1 -> 0.013059942 | F10: 45355 | G10: 3925.95 | I10: =G10/G9-1 -> 0.010761698
A11: 45362 | B11: 4057.5984 | D11: =B11/B10-1 -> 0.028262756 | F11: 45362 | G11: 3932.1001 | I11: =G11/G10-1 -> 0.0015665372 | K11: adjusted beta | L11: =L6*L5+L9*L8 -> 0.60500115
A12: 45369 | B12: 3942.4775 | D12: =B12/B11-1 -> -0.028371672 | F12: 45369 | G12: 4297.6001 | I12: =G12/G11-1 -> 0.092952873
A13: 45376 | B13: 3941.8782 | D13: =B13/B12-1 -> -0.00015202756 | F13: 45376 | G13: 4525.6001 | I13: =G13/G12-1 -> 0.053052866
A14: 45383 | B14: 3926.502 | D14: =B14/B13-1 -> -0.0039007346 | F14: 45383 | G14: 4619.25 | I14: =G14/G13-1 -> 0.020693367 | L14: SUMMARY OUTPUT
A15: 45390 | B15: 4047.564 | D15: =B15/B14-1 -> 0.030832026 | F15: 45390 | G15: 4765.0498 | I15: =G15/G14-1 -> 0.031563523
A16: 45397 | B16: 4152.501 | D16: =B16/B15-1 -> 0.025925967 | F16: 45397 | G16: 4696 | I16: =G16/G15-1 -> -0.014490888 | L16: Regression Statistics
A17: 45404 | B17: 4298.1748 | D17: =B17/B16-1 -> 0.035080986 | F17: 45404 | G17: 4553.1499 | I17: =G17/G16-1 -> -0.030419527 | L17: Multiple R | M17: 0.39246461
A18: 45411 | B18: 4516.6357 | D18: =B18/B17-1 -> 0.050826443 | F18: 45411 | G18: 4612.3501 | I18: =G18/G17-1 -> 0.013002031 | L18: R Square | M18: 0.15402847
A19: 45418 | B19: 4464.4668 | D19: =B19/B18-1 -> -0.011550399 | F19: 45418 | G19: 4796.7998 | I19: =G19/G18-1 -> 0.039990396 | L19: Adjusted R Square | M19: 0.14573463
A20: 45425 | B20: 4635.8003 | D20: =B20/B19-1 -> 0.038377146 | F20: 45425 | G20: 4670.6499 | I20: =G20/G19-1 -> -0.026298763 | L20: Standard Error | M20: 0.04839606
A21: 45432 | B21: 4708.0879 | D21: =B21/B20-1 -> 0.015593337 | F21: 45432 | G21: 4684.5 | I21: =G21/G20-1 -> 0.002965347 | L21: Observations | M21: 104
A22: 45439 | B22: 4555.2036 | D22: =B22/B21-1 -> -0.03247269 | F22: 45439 | G22: 4302.1499 | I22: =G22/G21-1 -> -0.081620258
A23: 45446 | B23: 4960.3027 | D23: =B23/B22-1 -> 0.088931068 | F23: 45446 | G23: 4747.25 | I23: =G23/G22-1 -> 0.10345992 | L23: ANOVA
A24: 45453 | B24: 5241.0093 | D24: =B24/B23-1 -> 0.056590607 | F24: 45453 | G24: 4739.9502 | I24: =G24/G23-1 -> -0.0015376912 | M24: df | N24: SS | O24: MS | P24: F | Q24: Significance F
A25: 45460 | B25: 5261.7915 | D25: =B25/B24-1 -> 0.00396531 | F25: 45460 | G25: 4804.8501 | I25: =G25/G24-1 -> 0.013692106 | L25: Regression | M25: 1 | N25: 0.043497614 | O25: 0.043497614 | P25: 18.571433 | Q25: 3.7790924e-05
A26: 45467 | B26: 5475.1069 | D26: =B26/B25-1 -> 0.040540457 | F26: 45467 | G26: 4716.75 | I26: =G26/G25-1 -> -0.01833566 | L26: Residual | M26: 102 | N26: 0.23890222 | O26: 0.0023421787
A27: 45474 | B27: 5615.0356 | D27: =B27/B26-1 -> 0.025557256 | F27: 45474 | G27: 4853.1001 | I27: =G27/G26-1 -> 0.028907637 | L27: Total | M27: 103 | N27: 0.28239984
A28: 45481 | B28: 5646.3584 | D28: =B28/B27-1 -> 0.0055783713 | F28: 45481 | G28: 4943.6499 | I28: =G28/G27-1 -> 0.018658137
A29: 45488 | B29: 5161.8784 | D29: =B29/B28-1 -> -0.085803972 | F29: 45488 | G29: 5010.7002 | I29: =G29/G28-1 -> 0.013562913 | M29: Coefficients | N29: Standard Error | O29: t Stat | P29: P-value | Q29: Lower 95% | R29: Upper 95% | S29: Lower 95.0% | T29: Upper 95.0%
A30: 45495 | B30: 5388.6816 | D30: =B30/B29-1 -> 0.043938118 | F30: 45495 | G30: 5071.6001 | I30: =G30/G29-1 -> 0.01215397 | L30: Intercept | M30: 0.0016181168 | N30: 0.0047479181 | O30: 0.34080553 | P30: 0.73395095 | Q30: -0.0077993563 | R30: 0.01103559 | S30: -0.0077993563 | T30: 0.01103559
A31: 45502 | B31: 5533.4561 | D31: =B31/B30-1 -> 0.026866388 | F31: 45502 | G31: 4909.7002 | I31: =G31/G30-1 -> -0.031922845 | L31: X Variable 1 | M31: 0.47333487 | N31: 0.10983627 | O31: 4.3094586 | P31: 3.7790924e-05 | Q31: 0.25547514 | R31: 0.69119459 | S31: 0.25547514 | T31: 0.69119459
A32: 45509 | B32: 6269.9185 | D32: =B32/B31-1 -> 0.13309266 | F32: 45509 | G32: 4989.9502 | I32: =G32/G31-1 -> 0.016345194
A33: 45516 | B33: 6496.7715 | D33: =B33/B32-1 -> 0.036181177 | F33: 45516 | G33: 5021.2998 | I33: =G33/G32-1 -> 0.0062825496
A34: 45523 | B34: 6942.7354 | D34: =B34/B33-1 -> 0.068643921 | F34: 45523 | G34: 4901.5 | I34: =G34/G33-1 -> -0.023858325
A35: 45530 | B35: 7152.5537 | D35: =B35/B34-1 -> 0.030221281 | F35: 45530 | G35: 4927.4502 | I35: =G35/G34-1 -> 0.0052943375
A36: 45537 | B36: 7097.4014 | D36: =B36/B35-1 -> -0.0077108605 | F36: 45537 | G36: 5303.4502 | I36: =G36/G35-1 -> 0.076307215
A37: 45544 | B37: 7226.8892 | D37: =B37/B36-1 -> 0.018244395 | F37: 45544 | G37: 5187.0498 | I37: =G37/G36-1 -> -0.02194805
A38: 45551 | B38: 7458.688 | D38: =B38/B37-1 -> 0.032074496 | F38: 45551 | G38: 5320.5498 | I38: =G38/G37-1 -> 0.025737173
A39: 45558 | B39: 7826.9194 | D39: =B39/B38-1 -> 0.049369466 | F39: 45558 | G39: 5102.2998 | I39: =G39/G38-1 -> -0.041020197
A40: 45565 | B40: 7346.9351 | D40: =B40/B39-1 -> -0.061324814 | F40: 45565 | G40: 4737.5498 | I40: =G40/G39-1 -> -0.071487371
A41: 45572 | B41: 8227.8223 | D41: =B41/B40-1 -> 0.1198986 | F41: 45572 | G41: 4572.7002 | I41: =G41/G40-1 -> -0.034796386
...

Sheet beta manavyar
O2: these are the three ways
B3: manvyavar | G3: nifty | K3: beta drifting | O3: of finding beta :
O4: beta 1 | P4: =SLOPE(D7:D110,I7:I110) -> 0.0033389176
A5: date | B5: prices | C5: weekly return | F5: date | G5: prices | H5: weekly return | K5: levered raw beta | L5: =P5 -> 0.0033389176 | O5: beta 2 | P5: =_xlfn.COVARIANCE.S(D6:D110,I6:I110)/_xlfn.VAR.S(I6:I110) -> 0.0033389176
A6: 45327 | B6: 947.68274 | F6: 45327 | G6: 3719.2 | K6: beta weigth | L6: 0.75 | O6: beta 3 | P6: =M30 -> 0.0033389176
A7: 45334 | B7: 955.14795 | D7: =B7/B6-1 -> 0.0078773303 | F7: 45334 | G7: 3693.3 | I7: =G7/G6-1 -> -0.006963837
A8: 45341 | B8: 967.72089 | D8: =B8/B7-1 -> 0.01316334 | F8: 45341 | G8: 3840.55 | I8: =G8/G7-1 -> 0.039869493 | K8: market beta | L8: 1
A9: 45348 | B9: 1006.1272 | D9: =B9/B8-1 -> 0.039687385 | F9: 45348 | G9: 3884.1499 | I9: =G9/G8-1 -> 0.011352502 | K9: market beta weight= | L9: 0.25
A10: 45355 | B10: 948.22302 | D10: =B10/B9-1 -> -0.057551545 | F10: 45355 | G10: 3925.95 | I10: =G10/G9-1 -> 0.010761698
A11: 45362 | B11: 908.98187 | D11: =B11/B10-1 -> -0.041383882 | F11: 45362 | G11: 3932.1001 | I11: =G11/G10-1 -> 0.0015665372 | K11: adjusted beta | L11: =L6*L5+L9*L8 -> 0.25250419
A12: 45369 | B12: 916.44702 | D12: =B12/B11-1 -> 0.0082126488 | F12: 45369 | G12: 4297.6001 | I12: =G12/G11-1 -> 0.092952873
A13: 45376 | B13: 910.06226 | D13: =B13/B12-1 -> -0.0069668682 | F13: 45376 | G13: 4525.6001 | I13: =G13/G12-1 -> 0.053052866 | L13: SUMMARY OUTPUT
A14: 45383 | B14: 893.51129 | D14: =B14/B13-1 -> -0.018186629 | F14: 45383 | G14: 4619.25 | I14: =G14/G13-1 -> 0.020693367
A15: 45390 | B15: 898.12781 | D15: =B15/B14-1 -> 0.0051667127 | F15: 45390 | G15: 4765.0498 | I15: =G15/G14-1 -> 0.031563523 | L15: Regression Statistics
A16: 45397 | B16: 902.00775 | D16: =B16/B15-1 -> 0.0043200353 | F16: 45397 | G16: 4696 | I16: =G16/G15-1 -> -0.014490888 | L16: Multiple R | M16: 0.0037010784
A17: 45404 | B17: 920.91626 | D17: =B17/B16-1 -> 0.020962689 | F17: 45404 | G17: 4553.1499 | I17: =G17/G16-1 -> -0.030419527 | L17: R Square | M17: 1.3697981e-05
A18: 45411 | B18: 916.05408 | D18: =B18/B17-1 -> -0.0052797228 | F18: 45411 | G18: 4612.3501 | I18: =G18/G17-1 -> 0.013002031 | L18: Adjusted R Square | M18: -0.0097900893
A19: 45418 | B19: 966.1001 | D19: =B19/B18-1 -> 0.054632168 | F19: 45418 | G19: 4796.7998 | I19: =G19/G18-1 -> 0.039990396 | L19: Standard Error | M19: 0.039358504
A20: 45425 | B20: 1025.4775 | D20: =B20/B19-1 -> 0.061460962 | F20: 45425 | G20: 4670.6499 | I20: =G20/G19-1 -> -0.026298763 | L20: Observations | M20: 104
A21: 45432 | B21: 1005.0467 | D21: =B21/B20-1 -> -0.019923252 | F21: 45432 | G21: 4684.5 | I21: =G21/G20-1 -> 0.002965347
A22: 45439 | B22: 1024.741 | D22: =B22/B21-1 -> 0.019595383 | F22: 45439 | G22: 4302.1499 | I22: =G22/G21-1 -> -0.081620258 | L22: ANOVA
A23: 45446 | B23: 1094.7268 | D23: =B23/B22-1 -> 0.068296128 | F23: 45446 | G23: 4747.25 | I23: =G23/G22-1 -> 0.10345992 | M23: df | N23: SS | O23: MS | P23: F | Q23: Significance F
A24: 45453 | B24: 1127.2888 | D24: =B24/B23-1 -> 0.029744418 | F24: 45453 | G24: 4739.9502 | I24: =G24/G23-1 -> -0.0015376912 | L24: Regression | M24: 1 | N24: 2.1644116e-06 | O24: 2.1644116e-06 | P24: 0.0013972132 | Q24: 0.97025562
A25: 45460 | B25: 1100.2766 | D25: =B25/B24-1 -> -0.0239621 | F25: 45460 | G25: 4804.8501 | I25: =G25/G24-1 -> 0.013692106 | L25: Residual | M25: 102 | N25: 0.15800737 | O25: 0.0015490919
A26: 45467 | B26: 1032.9919 | D26: =B26/B25-1 -> -0.061152502 | F26: 45467 | G26: 4716.75 | I26: =G26/G25-1 -> -0.01833566 | L26: Total | M26: 103 | N26: 0.15800953
A27: 45474 | B27: 1075.2291 | D27: =B27/B26-1 -> 0.040888201 | F27: 45474 | G27: 4853.1001 | I27: =G27/G26-1 -> 0.028907637
A28: 45481 | B28: 1007.8952 | D28: =B28/B27-1 -> -0.06262286 | F28: 45481 | G28: 4943.6499 | I28: =G28/G27-1 -> 0.018658137 | M28: Coefficients | N28: Standard Error | O28: t Stat | P28: P-value | Q28: Lower 95% | R28: Upper 95% | S28: Lower 95.0% | T28: Upper 95.0%
A29: 45488 | B29: 1017.9143 | D29: =B29/B28-1 -> 0.0099406208 | F29: 45488 | G29: 5010.7002 | I29: =G29/G28-1 -> 0.013562913 | L29: Intercept | M29: -0.005941892 | N29: 0.0038612845 | O29: -1.5388382 | P29: 0.12694035 | Q29: -0.013600731 | R29: 0.0017169474 | S29: -0.013600731 | T29: 0.0017169474
A30: 45495 | B30: 1063.5894 | D30: =B30/B29-1 -> 0.044871212 | F30: 45495 | G30: 5071.6001 | I30: =G30/G29-1 -> 0.01215397 | L30: X Variable 1 | M30: 0.0033389176 | N30: 0.089325276 | O30: 0.037379315 | P30: 0.97025562 | Q30: -0.17383734 | R30: 0.18051518 | S30: -0.17383734 | T30: 0.18051518
A31: 45502 | B31: 1118.0554 | D31: =B31/B30-1 -> 0.051209674 | F31: 45502 | G31: 4909.7002 | I31: =G31/G30-1 -> -0.031922845
A32: 45509 | B32: 1101.5045 | D32: =B32/B31-1 -> -0.014803294 | F32: 45509 | G32: 4989.9502 | I32: =G32/G31-1 -> 0.016345194
A33: 45516 | B33: 1101.6027 | D33: =B33/B32-1 -> 8.9100435e-05 | F33: 45516 | G33: 5021.2998 | I33: =G33/G32-1 -> 0.0062825496
A34: 45523 | B34: 1153.4167 | D34: =B34/B33-1 -> 0.047035187 | F34: 45523 | G34: 4901.5 | I34: =G34/G33-1 -> -0.023858325
A35: 45530 | B35: 1237.204 | D35: =B35/B34-1 -> 0.072642635 | F35: 45530 | G35: 4927.4502 | I35: =G35/G34-1 -> 0.0052943375
A36: 45537 | B36: 1236.0662 | D36: =B36/B35-1 -> -0.00091966838 | F36: 45537 | G36: 5303.4502 | I36: =G36/G35-1 -> 0.076307215
A37: 45544 | B37: 1273.2198 | D37: =B37/B36-1 -> 0.030058008 | F37: 45544 | G37: 5187.0498 | I37: =G37/G36-1 -> -0.02194805
A38: 45551 | B38: 1278.6619 | D38: =B38/B37-1 -> 0.004274216 | F38: 45551 | G38: 5320.5498 | I38: =G38/G37-1 -> 0.025737173
A39: 45558 | B39: 1336.4454 | D39: =B39/B38-1 -> 0.045190657 | F39: 45558 | G39: 5102.2998 | I39: =G39/G38-1 -> -0.041020197
A40: 45565 | B40: 1285.1921 | D40: =B40/B39-1 -> -0.038350459 | F40: 45565 | G40: 4737.5498 | I40: =G40/G39-1 -> -0.071487371
A41: 45572 | B41: 1306.119 | D41: =B41/B40-1 -> 0.016283075 | F41: 45572 | G41: 4572.7002 | I41: =G41/G40-1 -> -0.034796386
...

Sheet beta abfrl
O2: these are the three ways
B3: abfrl | G3: nifty | K3: beta drifting | O3: of finding beta :
O4: beta 1 | P4: =SLOPE(D7:D110,I7:I110) -> 0.34585093
A5: date | B5: prices | C5: weekly return | F5: date | G5: prices | H5: weekly return | K5: levered raw beta | L5: =P5 -> 0.34585093 | O5: beta 2 | P5: =_xlfn.COVARIANCE.S(D6:D110,I6:I110)/_xlfn.VAR.S(I6:I110) -> 0.34585093
A6: 45327 | B6: 252.85001 | F6: 45327 | G6: 3719.2 | K6: beta weigth | L6: 0.75 | O6: beta 3 | P6: =M30 -> 0.34585093
A7: 45334 | B7: 230.85001 | D7: =B7/B6-1 -> -0.087008105 | F7: 45334 | G7: 3693.3 | I7: =G7/G6-1 -> -0.006963837
A8: 45341 | B8: 226.2 | D8: =B8/B7-1 -> -0.020142989 | F8: 45341 | G8: 3840.55 | I8: =G8/G7-1 -> 0.039869493 | K8: market beta | L8: 1
A9: 45348 | B9: 229.75 | D9: =B9/B8-1 -> 0.01569409 | F9: 45348 | G9: 3884.1499 | I9: =G9/G8-1 -> 0.011352502 | K9: market beta weight= | L9: 0.25
A10: 45355 | B10: 225.39999 | D10: =B10/B9-1 -> -0.01893365 | F10: 45355 | G10: 3925.95 | I10: =G10/G9-1 -> 0.010761698
A11: 45362 | B11: 207.35001 | D11: =B11/B10-1 -> -0.080079806 | F11: 45362 | G11: 3932.1001 | I11: =G11/G10-1 -> 0.0015665372 | K11: adjusted beta | L11: =L6*L5+L9*L8 -> 0.5093882
A12: 45369 | B12: 205.35001 | D12: =B12/B11-1 -> -0.0096455266 | F12: 45369 | G12: 4297.6001 | I12: =G12/G11-1 -> 0.092952873
A13: 45376 | B13: 205.55 | D13: =B13/B12-1 -> 0.00097393203 | F13: 45376 | G13: 4525.6001 | I13: =G13/G12-1 -> 0.053052866 | L13: SUMMARY OUTPUT
A14: 45383 | B14: 237.35001 | D14: =B14/B13-1 -> 0.1547069 | F14: 45383 | G14: 4619.25 | I14: =G14/G13-1 -> 0.020693367
A15: 45390 | B15: 233.95 | D15: =B15/B14-1 -> -0.014324875 | F15: 45390 | G15: 4765.0498 | I15: =G15/G14-1 -> 0.031563523 | L15: Regression Statistics
A16: 45397 | B16: 231.55 | D16: =B16/B15-1 -> -0.010258576 | F16: 45397 | G16: 4696 | I16: =G16/G15-1 -> -0.014490888 | L16: Multiple R | M16: 0.17980454
A17: 45404 | B17: 268.54999 | D17: =B17/B16-1 -> 0.15979263 | F17: 45404 | G17: 4553.1499 | I17: =G17/G16-1 -> -0.030419527 | L17: R Square | M17: 0.032329671
A18: 45411 | B18: 254.14999 | D18: =B18/B17-1 -> -0.053621279 | F18: 45411 | G18: 4612.3501 | I18: =G18/G17-1 -> 0.013002031 | L18: Adjusted R Square | M18: 0.022842707
A19: 45418 | B19: 256.85001 | D19: =B19/B18-1 -> 0.010623696 | F19: 45418 | G19: 4796.7998 | I19: =G19/G18-1 -> 0.039990396 | L19: Standard Error | M19: 0.082549824
A20: 45425 | B20: 264.04999 | D20: =B20/B19-1 -> 0.028031853 | F20: 45425 | G20: 4670.6499 | I20: =G20/G19-1 -> -0.026298763 | L20: Observations | M20: 104
A21: 45432 | B21: 290.04999 | D21: =B21/B20-1 -> 0.098466204 | F21: 45432 | G21: 4684.5 | I21: =G21/G20-1 -> 0.002965347
A22: 45439 | B22: 287.64999 | D22: =B22/B21-1 -> -0.0082744147 | F22: 45439 | G22: 4302.1499 | I22: =G22/G21-1 -> -0.081620258 | L22: ANOVA
A23: 45446 | B23: 324.20001 | D23: =B23/B22-1 -> 0.12706421 | F23: 45446 | G23: 4747.25 | I23: =G23/G22-1 -> 0.10345992 | M23: df | N23: SS | O23: MS | P23: F | Q23: Significance F
A24: 45453 | B24: 328.60001 | D24: =B24/B23-1 -> 0.01357185 | F24: 45453 | G24: 4739.9502 | I24: =G24/G23-1 -> -0.0015376912 | L24: Regression | M24: 1 | N24: 0.023222359 | O24: 0.023222359 | P24: 3.4077995 | Q24: 0.067788955
A25: 45460 | B25: 314.89999 | D25: =B25/B24-1 -> -0.041692063 | F25: 45460 | G25: 4804.8501 | I25: =G25/G24-1 -> 0.013692106 | L25: Residual | M25: 102 | N25: 0.69507629 | O25: 0.0068144734
A26: 45467 | B26: 312.14999 | D26: =B26/B25-1 -> -0.0087329313 | F26: 45467 | G26: 4716.75 | I26: =G26/G25-1 -> -0.01833566 | L26: Total | M26: 103 | N26: 0.71829865
A27: 45474 | B27: 327.64999 | D27: =B27/B26-1 -> 0.049655615 | F27: 45474 | G27: 4853.1001 | I27: =G27/G26-1 -> 0.028907637
A28: 45481 | B28: 323.20001 | D28: =B28/B27-1 -> -0.01358151 | F28: 45481 | G28: 4943.6499 | I28: =G28/G27-1 -> 0.018658137 | M28: Coefficients | N28: Standard Error | O28: t Stat | P28: P-value | Q28: Lower 95% | R28: Upper 95% | S28: Lower 95.0% | T28: Upper 95.0%
A29: 45488 | B29: 315.60001 | D29: =B29/B28-1 -> -0.023514869 | F29: 45488 | G29: 5010.7002 | I29: =G29/G28-1 -> 0.013562913 | L29: Intercept | M29: -0.0073011928 | N29: 0.0080985891 | O29: -0.90153887 | P29: 0.36942574 | Q29: -0.023364706 | R29: 0.0087623202 | S29: -0.023364706 | T29: 0.0087623202
A30: 45495 | B30: 330 | D30: =B30/B29-1 -> 0.045627356 | F30: 45495 | G30: 5071.6001 | I30: =G30/G29-1 -> 0.01215397 | L30: X Variable 1 | M30: 0.34585093 | N30: 0.18734924 | O30: 1.8460226 | P30: 0.067788955 | Q30: -0.025755396 | R30: 0.71745725 | S30: -0.025755396 | T30: 0.71745725
A31: 45502 | B31: 335.5 | D31: =B31/B30-1 -> 0.016666667 | F31: 45502 | G31: 4909.7002 | I31: =G31/G30-1 -> -0.031922845
A32: 45509 | B32: 324.70001 | D32: =B32/B31-1 -> -0.032190724 | F32: 45509 | G32: 4989.9502 | I32: =G32/G31-1 -> 0.016345194
A33: 45516 | B33: 319.45001 | D33: =B33/B32-1 -> -0.016168771 | F33: 45516 | G33: 5021.2998 | I33: =G33/G32-1 -> 0.0062825496
A34: 45523 | B34: 319.5 | D34: =B34/B33-1 -> 0.0001564808 | F34: 45523 | G34: 4901.5 | I34: =G34/G33-1 -> -0.023858325
A35: 45530 | B35: 311.70001 | D35: =B35/B34-1 -> -0.024413107 | F35: 45530 | G35: 4927.4502 | I35: =G35/G34-1 -> 0.0052943375
A36: 45537 | B36: 309.14999 | D36: =B36/B35-1 -> -0.0081810016 | F36: 45537 | G36: 5303.4502 | I36: =G36/G35-1 -> 0.076307215
A37: 45544 | B37: 328.54999 | D37: =B37/B36-1 -> 0.062752691 | F37: 45544 | G37: 5187.0498 | I37: =G37/G36-1 -> -0.02194805
A38: 45551 | B38: 327.75 | D38: =B38/B37-1 -> -0.0024349043 | F38: 45551 | G38: 5320.5498 | I38: =G38/G37-1 -> 0.025737173
A39: 45558 | B39: 352.10001 | D39: =B39/B38-1 -> 0.07429445 | F39: 45558 | G39: 5102.2998 | I39: =G39/G38-1 -> -0.041020197
A40: 45565 | B40: 333 | D40: =B40/B39-1 -> -0.054245969 | F40: 45565 | G40: 4737.5498 | I40: =G40/G39-1 -> -0.071487371
A41: 45572 | B41: 340.25 | D41: =B41/B40-1 -> 0.021771772 | F41: 45572 | G41: 4572.7002 | I41: =G41/G40-1 -> -0.034796386
...

Sheet beta mterobrand
O2: these are the three ways
B3: metrobrand | G3: nifty | K3: beta drifting | O3: of finding beta :
O4: beta 1 | P4: =SLOPE(D7:D110,I7:I110) -> 0.037661612
A5: date | B5: prices | C5: weekly return | F5: date | G5: prices | H5: weekly return | K5: levered raw beta | L5: =P5 -> 0.037661612 | O5: beta 2 | P5: =_xlfn.COVARIANCE.S(D6:D110,I6:I110)/_xlfn.VAR.S(I6:I110) -> 0.037661612
A6: 45327 | B6: 1075.9277 | F6: 45327 | G6: 3719.2 | K6: beta weigth | L6: 0.75 | O6: beta 3 | P6: =M31 -> 0.037661612
A7: 45334 | B7: 1098.6169 | D7: =B7/B6-1 -> 0.021088042 | F7: 45334 | G7: 3693.3 | I7: =G7/G6-1 -> -0.006963837
A8: 45341 | B8: 1113.7756 | D8: =B8/B7-1 -> 0.013797977 | F8: 45341 | G8: 3840.55 | I8: =G8/G7-1 -> 0.039869493 | K8: market beta | L8: 1
A9: 45348 | B9: 1120.7192 | D9: =B9/B8-1 -> 0.0062342929 | F9: 45348 | G9: 3884.1499 | I9: =G9/G8-1 -> 0.011352502 | K9: market beta weight= | L9: 0.25
A10: 45355 | B10: 1109.3259 | D10: =B10/B9-1 -> -0.01016607 | F10: 45355 | G10: 3925.95 | I10: =G10/G9-1 -> 0.010761698
A11: 45362 | B11: 1054.9989 | D11: =B11/B10-1 -> -0.048973007 | F11: 45362 | G11: 3932.1001 | I11: =G11/G10-1 -> 0.0015665372 | K11: adjusted beta | L11: =L6*L5+L9*L8 -> 0.27824621
A12: 45369 | B12: 1097.3457 | D12: =B12/B11-1 -> 0.04013919 | F12: 45369 | G12: 4297.6001 | I12: =G12/G11-1 -> 0.092952873
A13: 45376 | B13: 1128.5432 | D13: =B13/B12-1 -> 0.028429974 | F13: 45376 | G13: 4525.6001 | I13: =G13/G12-1 -> 0.053052866
A14: 45383 | B14: 1055.6835 | D14: =B14/B13-1 -> -0.064560878 | F14: 45383 | G14: 4619.25 | I14: =G14/G13-1 -> 0.020693367 | L14: SUMMARY OUTPUT
A15: 45390 | B15: 1026.0995 | D15: =B15/B14-1 -> -0.028023537 | F15: 45390 | G15: 4765.0498 | I15: =G15/G14-1 -> 0.031563523
A16: 45397 | B16: 1045.3168 | D16: =B16/B15-1 -> 0.018728481 | F16: 45397 | G16: 4696 | I16: =G16/G15-1 -> -0.014490888 | L16: Regression Statistics
A17: 45404 | B17: 1058.3729 | D17: =B17/B16-1 -> 0.01249014 | F17: 45404 | G17: 4553.1499 | I17: =G17/G16-1 -> -0.030419527 | L17: Multiple R | M17: 0.043005618
A18: 45411 | B18: 1044.7791 | D18: =B18/B17-1 -> -0.012844123 | F18: 45411 | G18: 4612.3501 | I18: =G18/G17-1 -> 0.013002031 | L18: R Square | M18: 0.0018494832
A19: 45418 | B19: 1014.5104 | D19: =B19/B18-1 -> -0.028971308 | F19: 45418 | G19: 4796.7998 | I19: =G19/G18-1 -> 0.039990396 | L19: Adjusted R Square | M19: -0.0079363062
A20: 45425 | B20: 1121.8931 | D20: =B20/B19-1 -> 0.10584675 | F20: 45425 | G20: 4670.6499 | I20: =G20/G19-1 -> -0.026298763 | L20: Standard Error | M20: 0.038171204
A21: 45432 | B21: 1116.2207 | D21: =B21/B20-1 -> -0.0050560641 | F21: 45432 | G21: 4684.5 | I21: =G21/G20-1 -> 0.002965347 | L21: Observations | M21: 104
A22: 45439 | B22: 1110.5483 | D22: =B22/B21-1 -> -0.0050817578 | F22: 45439 | G22: 4302.1499 | I22: =G22/G21-1 -> -0.081620258
A23: 45446 | B23: 1130.4014 | D23: =B23/B22-1 -> 0.017876779 | F23: 45446 | G23: 4747.25 | I23: =G23/G22-1 -> 0.10345992 | L23: ANOVA
A24: 45453 | B24: 1124.8759 | D24: =B24/B23-1 -> -0.004888098 | F24: 45453 | G24: 4739.9502 | I24: =G24/G23-1 -> -0.0015376912 | M24: df | N24: SS | O24: MS | P24: F | Q24: Significance F
A25: 45460 | B25: 1232.5028 | D25: =B25/B24-1 -> 0.095678961 | F25: 45460 | G25: 4804.8501 | I25: =G25/G24-1 -> 0.013692106 | L25: Regression | M25: 1 | N25: 0.0002753761 | O25: 0.0002753761 | P25: 0.18899683 | Q25: 0.66467123
A26: 45467 | B26: 1201.4517 | D26: =B26/B25-1 -> -0.025193571 | F26: 45467 | G26: 4716.75 | I26: =G26/G25-1 -> -0.01833566 | L26: Residual | M26: 102 | N26: 0.14861817 | O26: 0.0014570408
A27: 45474 | B27: 1190.645 | D27: =B27/B26-1 -> -0.0089946529 | F27: 45474 | G27: 4853.1001 | I27: =G27/G26-1 -> 0.028907637 | L27: Total | M27: 103 | N27: 0.14889354
A28: 45481 | B28: 1300.3258 | D28: =B28/B27-1 -> 0.092118796 | F28: 45481 | G28: 4943.6499 | I28: =G28/G27-1 -> 0.018658137
A29: 45488 | B29: 1283.0643 | D29: =B29/B28-1 -> -0.01327473 | F29: 45488 | G29: 5010.7002 | I29: =G29/G28-1 -> 0.013562913 | M29: Coefficients | N29: Standard Error | O29: t Stat | P29: P-value | Q29: Lower 95% | R29: Upper 95% | S29: Lower 95.0% | T29: Upper 95.0%
A30: 45495 | B30: 1284.7272 | D30: =B30/B29-1 -> 0.0012959925 | F30: 45495 | G30: 5071.6001 | I30: =G30/G29-1 -> 0.01215397 | L30: Intercept | M30: 0.0002640441 | N30: 0.0037448038 | O30: 0.07050946 | P30: 0.94392623 | Q30: -0.0071637566 | R30: 0.0076918447 | S30: -0.0071637566 | T30: 0.0076918447
A31: 45502 | B31: 1319.9833 | D31: =B31/B30-1 -> 0.027442483 | F31: 45502 | G31: 4909.7002 | I31: =G31/G30-1 -> -0.031922845 | L31: X Variable 1 | M31: 0.037661612 | N31: 0.086630663 | O31: 0.43473766 | P31: 0.66467123 | Q31: -0.1341699 | R31: 0.20949312 | S31: -0.1341699 | T31: 0.20949312
A32: 45509 | B32: 1314.262 | D32: =B32/B31-1 -> -0.0043343833 | F32: 45509 | G32: 4989.9502 | I32: =G32/G31-1 -> 0.016345194
A33: 45516 | B33: 1299.3479 | D33: =B33/B32-1 -> -0.011347861 | F33: 45516 | G33: 5021.2998 | I33: =G33/G32-1 -> 0.0062825496
A34: 45523 | B34: 1310.5947 | D34: =B34/B33-1 -> 0.0086557466 | F34: 45523 | G34: 4901.5 | I34: =G34/G33-1 -> -0.023858325
A35: 45530 | B35: 1277.2944 | D35: =B35/B34-1 -> -0.025408536 | F35: 45530 | G35: 4927.4502 | I35: =G35/G34-1 -> 0.0052943375
A36: 45537 | B36: 1207.1241 | D36: =B36/B35-1 -> -0.054936658 | F36: 45537 | G36: 5303.4502 | I36: =G36/G35-1 -> 0.076307215
A37: 45544 | B37: 1238.7031 | D37: =B37/B36-1 -> 0.026160507 | F37: 45544 | G37: 5187.0498 | I37: =G37/G36-1 -> -0.02194805
A38: 45551 | B38: 1221.2642 | D38: =B38/B37-1 -> -0.014078405 | F38: 45551 | G38: 5320.5498 | I38: =G38/G37-1 -> 0.025737173
A39: 45558 | B39: 1249.8718 | D39: =B39/B38-1 -> 0.023424634 | F39: 45558 | G39: 5102.2998 | I39: =G39/G38-1 -> -0.041020197
A40: 45565 | B40: 1229.7876 | D40: =B40/B39-1 -> -0.016069031 | F40: 45565 | G40: 4737.5498 | I40: =G40/G39-1 -> -0.071487371
A41: 45572 | B41: 1200.7391 | D41: =B41/B40-1 -> -0.023620715 | F41: 45572 | G41: 4572.7002 | I41: =G41/G40-1 -> -0.034796386
...

Sheet comps closing prices
A1: Date | B1: TRENT | C1: MANYAVAR | D1: ABFRL | E1: ADN | F1: METROBRAND
A2: 45327 | B2: 3753.7205 | C2: 947.68274 | D2: 252.85001 | E2: 3212.3511 | F2: 1075.9277
A3: 45334 | B3: 4018.3594 | C3: 955.14795 | D3: 230.85001 | E3: 3220.7437 | F3: 1098.6169
A4: 45341 | B4: 3879.7747 | C4: 967.72089 | D4: 226.2 | E4: 3270.3997 | F4: 1113.7756
A5: 45348 | B5: 3895.2004 | C5: 1006.1272 | D5: 229.75 | E5: 3315.8091 | F5: 1120.7192
A6: 45355 | B6: 3946.0715 | C6: 948.22302 | D6: 225.39999 | E6: 3223.6909 | F6: 1109.3259
A7: 45362 | B7: 4057.5984 | C7: 908.98187 | D7: 207.35001 | E7: 3129.4243 | F7: 1054.9989
A8: 45369 | B8: 3942.4775 | C8: 916.44702 | D8: 205.35001 | E8: 3104.9463 | F8: 1097.3457
A9: 45376 | B9: 3941.8782 | C9: 910.06226 | D9: 205.55 | E9: 3194.2671 | F9: 1128.5432
A10: 45383 | B10: 3926.502 | C10: 893.51129 | D10: 237.35001 | E10: 3221.9424 | F10: 1055.6835
A11: 45390 | B11: 4047.564 | C11: 898.12781 | D11: 233.95 | E11: 3207.0554 | F11: 1026.0995
A12: 45397 | B12: 4152.501 | C12: 902.00775 | D12: 231.55 | E12: 3024.2678 | F12: 1045.3168
A13: 45404 | B13: 4298.1748 | C13: 920.91626 | D13: 268.54999 | E13: 3077.6702 | F13: 1058.3729
... A106: 46055 | B106: 4113.7998 | C106: 470.75 | D106: 68.82 | E106: 2226.3999 | F106: 1032.7422

Sheet beta-comps
C4: Ticker | D4: Market Cap | E4: Total Debt | F4: Debt to Equity
C5: DMART.NS | D5: 2605665222656 | E5: 16091899904 | F5: 7.031
C6: TRENT.NS | D6: 1489847975936 | E6: 23485700096 | F6: 37.79
C7: MANYAVAR.NS | D7: 118461530112 | E7: 4637550080 | F7: 26.948
C8: ABFRL.NS | D8: 85499035648 | E8: 56652398592 | F8: 84.682
C9: METROBRAND.NS | D9: 285401055232 | E9: 14386299904 | F9: 77.874

Sheet valuation of rm
B2: (this data has benn extracted from prime investor.in)
C4: NIFTY yearly returns from 2000 to 2025
B6: Year | D6: Annual
B7: 2000 | D7: -0.1465
B8: 2001 | D8: -0.1618
B9: 2002 | D9: 0.0325 | F9: average return | H9: =AVERAGE(D7:D32) -> 0.15149231
B10: 2003 | D10: 0.719 | F10: dividend yield | H10: 1.39%1
B11: 2004 | D11: 0.1068 | F11: total market return | H11: =H9 -> 0.15149231
B12: 2005 | D12: 0.3634
B13: 2006 | D13: 0.3983
B14: 2007 | D14: 0.5477
B15: 2008 | D15: -0.5179
B16: 2009 | D16: 0.7576
B17: 2010 | D17: 0.1795
B18: 2011 | D18: -0.2462
B19: 2012 | D19: 0.277
B20: 2013 | D20: 0.0676
B21: 2014 | D21: 0.3139
B22: 2015 | D22: -0.0406
B23: 2016 | D23: 0.0301
... B32: 2025 | D32: 0.1051
